Workbook
Name A156A1: '🗂️ Proyectos'!$A$156

Sheet BBDD
A1: Proyecto | B1: Responsable | C1: Lámpara | D1: Estado | E1: Área | F1: Proceso | G1: TIPO DE BASTIDOR | H1: General | I1: Proceso | J1: Hrs/m
A2: Ikon Light system | B2: Claudio Peralta | C2: Cruz | D2: Pendiente | E2: CNC | F2: CNC | G2: BASTIDOR DE TABICA 150X12 | H2: CNC | I2: CNC | J2: 0.2 | P2: HRS | Q2: MIN
A3: Contract + | B3: Ihor Alieksieiev | C3: Parafarmacia | D3: Proceso | E3: Fabricación | F3: Corte manual | G3: BASTIDOR DE TABICA 150X12 | H3: Fabricación | I3: Ensamblaje | J3: 0.62 | L3: IMPRIMACION M2 | M3: Pintura | N3: Lijado y/o Masillado | O3: 0.1 | P3: =O3*1.4 -> 0.14 | Q3: =P3*60 -> 8.4
A4: Ceilica | B4: Serhii Kotluienko | C4: Gracos | D4: Terminada | E4: Fabricación | F4: Ensamblaje | G4: BASTIDOR DE TABICA 150X12 | H4: Fabricación | I4: Colocación de perfiles | J4: 0.2 | L4: IMPRIMACION M2 | M4: Pintura | N4: Imprimación/Pintura | O4: 0.19 | P4: =O4*1.4 -> 0.266 | Q4: =P4*60 -> 15.96
A5: Cullera | B5: Tetiana Mesriakin | C5: Gracos 2 | E5: Pintura | F5: Lijado y/o Masillado | G5: BASTIDOR DE TABICA 150X12 | H5: Fabricación | I5: Embalaje/carga/descarga material | J5: 0.15 | L5: PINTURA M2 | M5: Pintura | N5: Lijado y/o Masillado | O5: 0.15 | P5: =O5*0.39 -> 0.0585 | Q5: =P5*60 -> 3.51
A6: Picanya | B6: John Castelblanco | C6: Hair | E6: Fabricación | F6: Colocación de perfiles | G6: BASTIDOR DE TABICA 150X12 | H6: Pintura | I6: Lijado y/o Masillado | J6: 0.5 | L6: PINTURA M2 | M6: Pintura | N6: Imprimación/Pintura | O6: 0.28 | P6: =O6*0.39 -> 0.1092 | Q6: =P6*60 -> 6.552
A7: Druni cc la Villa (Canarias) | B7: Cesar Rodriguez | C7: Palmera | E7: Pintura | F7: Imprimación/Pintura | G7: BASTIDOR DE TABICA 150X12 | H7: Pintura | I7: Imprimación/Pintura | J7: 0.4 | L7: IMPRIMACION TABICA TRASERA | M7: Pintura | N7: Lijado y/o Masillado | O7: 0.21
A8: Druni cc las arenas (Canarias) | B8: Instalador | C8: Techo palmera | E8: Fabricación | F8: Pegado de composite/chapa | G8: BASTIDOR DE TABICA 150X12 COMPLETO | H8: CNC | I8: CNC | J8: =J2 -> 0.2 | L8: IMPRIMACION TABICA TRASERA | M8: Pintura | N8: Imprimación/Pintura | O8: 0.315
A9: Druni Cordoba fase 2 | B9: Daniil Shcheglov | C9: Pilar Palmera | E9: Fabricación | F9: Embalaje/carga/descarga material | G9: BASTIDOR DE TABICA 150X12 COMPLETO | H9: Fabricación | I9: Ensamblaje | J9: =J3 -> 0.62
A10: BYD Tarragona | C10: Mueble palmera | E10: Limpieza | F10: Limpieza | G10: BASTIDOR DE TABICA 150X12 COMPLETO | H10: Fabricación | I10: Colocación de perfiles | J10: =J4 -> 0.2
A11: BYD Paterna | C11: Prototipo | E11: Fabricación | F11: Supervisión/reunión | G11: BASTIDOR DE TABICA 150X12 COMPLETO | H11: Fabricación | I11: Embalaje/carga/descarga material | J11: =J5 -> 0.15
A12: Prototipo | C12: Selcos | E12: Producción | F12: Inventario | G12: BASTIDOR DE TABICA 150X12 COMPLETO | H12: Pintura | I12: Lijado y/o Masillado | J12: =J6+0.315 -> 0.815
A13: Arenal CC Marineda | C13: Selcos metacrilato | E13: Fabricación | F13: Transporte material | G13: BASTIDOR DE TABICA 150X12 COMPLETO | H13: Pintura | I13: Imprimación/Pintura | J13: =J7+0.21 -> 0.61
A14: Prueba | C14: Cromado | E14: Fabricación | F14: Descarga de material | G14: BASTIDOR DE TABICA CURVA 150X12 | H14: CNC | I14: CNC | J14: 0.2
A15: Arenal el rosal | C15: Ameba | E15: Pintura | F15: Limpieza de cabina | G15: BASTIDOR DE TABICA CURVA 150X12 | H15: Fabricación | I15: Ensamblaje | J15: 0.79
A16: Druni cc Lìlla | C16: Punto | E16: Limpieza | F16: Limpieza puesto de trabajo | G16: BASTIDOR DE TABICA CURVA 150X12 | H16: Fabricación | I16: Colocación de perfiles | J16: 0.2
A17: Hotel - Ana | C17: Producción | E17: Fabricación | F17: Mantenimiento | G17: BASTIDOR DE TABICA CURVA 150X12 | H17: Fabricación | I17: Embalaje/carga/descarga material | J17: 0.15
A18: Druni CC los alcores | C18: Curvas madera | E18: Fabricación | F18: Colocar tela | G18: BASTIDOR DE TABICA CURVA 150X12 | H18: Pintura | I18: Lijado y/o Masillado | J18: 0.6
A19: Druni Corralejo | C19: Revestimiento | E19: Fabricación | F19: Trabajo en nave 3 | G19: BASTIDOR DE TABICA CURVA 150X12 | H19: Pintura | I19: Imprimación/Pintura | J19: 0.4
A20: Druni Morrojable | C20: Ranura para placas | E20: Fabricación | F20: Preparación de material | G20: BASTIDOR DE TABICA CURVA 150X12 COMPLETO | H20: CNC | I20: CNC | J20: 0.2
A21: Proveedor | C21: Canopi | G21: BASTIDOR DE TABICA CURVA 150X12 COMPLETO | H21: Fabricación | I21: Ensamblaje | J21: 0.79
A22: Inventario | C22: Arandelas | G22: BASTIDOR DE TABICA CURVA 150X12 COMPLETO | H22: Fabricación | I22: Colocación de perfiles | J22: 0.2
A23: Druni CC Safari | C23: Caja chapa | G23: BASTIDOR DE TABICA CURVA 150X12 COMPLETO | H23: Fabricación | I23: Embalaje/carga/descarga material | J23: 0.15
A24: Druni CC Meridiano fase 2 | C24: Plantillas | G24: BASTIDOR DE TABICA CURVA 150X12 COMPLETO | H24: Pintura | I24: Lijado y/o Masillado | J24: =J18+0.315 -> 0.915
A25: Druni CC Biosfera | C25: Escalera | G25: BASTIDOR DE TABICA CURVA 150X12 COMPLETO | H25: Pintura | I25: Imprimación/Pintura | J25: =J19+0.21 -> 0.61
A26: Urbysol | C26: Nave | G26: BASTIDOR NORMAL 150 | H26: CNC | I26: CNC | J26: =J32+(2/50.54) -> 0.38957262
A27: Druni Catarroja | C27: Transporte | G27: BASTIDOR NORMAL 150 | H27: Fabricación | I27: Ensamblaje | J27: =1+(3.5/50.54) -> 1.0692521
A28: Druni Aguilas | C28: Bastidor Sol | G28: BASTIDOR NORMAL 150 | H28: Fabricación | I28: Colocación de perfiles | J28: 0.2
A29: Arenal Ourense | C29: Bastidor Sol plus | G29: BASTIDOR NORMAL 150 | H29: Fabricación | I29: Embalaje/carga/descarga material | J29: =0.15+(0.5/50.54) -> 0.15989315
A30: BYD Paterna | C30: Carga de lámparas/material | G30: BASTIDOR NORMAL 150 | H30: Pintura | I30: Lijado y/o Masillado | J30: =0.6+0.005+0.00055 -> 0.60555
A31: Estudio Ama | C31: Varias lamparas | G31: BASTIDOR NORMAL 150 | H31: Pintura | I31: Imprimación/Pintura | J31: =0.5+(0.009)+(0.0005)+0.014 -> 0.5235
A32: Casadecor | C32: Machimbrado | G32: BASTIDOR NORMAL 100 | H32: CNC | I32: CNC | J32: 0.35
A33: Druni Maisonnave Alicante | C33: supervisión | G33: BASTIDOR NORMAL 100 | H33: Fabricación | I33: Ensamblaje | J33: 1
A34: Novodecor | C34: Gestión nave | G34: BASTIDOR NORMAL 100 | H34: Fabricación | I34: Colocación de perfiles | J34: 0.2
A35: Druni Torre del mar | C35: Registro | G35: BASTIDOR NORMAL 100 | H35: Fabricación | I35: Embalaje/carga/descarga material | J35: 0.15
A36: Druni cc la Vie | C36: Perfil tela | G36: BASTIDOR NORMAL 100 | H36: Pintura | I36: Lijado y/o Masillado | J36: 0.6
A37: NOVODECOR Delybreads | C37: Perfil grand | G37: BASTIDOR NORMAL 100 | H37: Pintura | I37: Imprimación/Pintura | J37: 0.5
A38: Druni cc Leon | C38: Pasillo | G38: BASTIDOR NORMAL 50 | H38: CNC | I38: CNC | J38: 0.29
A39: Arenal vialia | C39: Bastidor normal 150 | G39: BASTIDOR NORMAL 50 | H39: Fabricación | I39: Ensamblaje | J39: 1
A40: Druni X Madrid | C40: Bastidor normal 100 | G40: BASTIDOR NORMAL 50 | H40: Fabricación | I40: Colocación de perfiles | J40: 0.2
...

Sheet 🗂️ Proyectos
A1: Proyecto | B1: Lampara | C1: Tipo_bastidor | D1: Medida | E1: Fecha_de_entrega | F1: Área | G1: Proceso | H1: Hr_plan | I1: Hr_total | J1: Hr_normal | K1: Hr_extra | L1: Prom/hr | M1: Hr_Pend | N1: Desviación | O1: %_Avance | P1: Estado | Q1: Estado_proyecto | R1: Avance
A2: Druni CC los alcores | B2: Gracos 2 | C2: BASTIDOR NORMAL 150 | D2: 50.54 | E2: 46080 | F2: CNC | G2: CNC | H2: =IFERROR(__xludf.DUMMYFUNCTION("(IFERROR(FILTER(BBDD!$J:$J,BBDD!$G:$G=C2,BBDD!$H:$H=F2,BBDD!$I:$I=G2),""NO TIENE PROCESO""))*D2"),19.689) -> 19.689 | I2: =J2+K2 -> 16.49 | J2: =SUMIFS('👷horas'!$J:$J,'👷horas'!$D:$D,A2,'👷horas'!$E:$E,B2,'👷horas'!$F:$F,F2,'👷horas'!$G:$G,G2) -> 16.49 | K2: =SUMIFS('👷horas'!$K:$K,'👷horas'!$D:$D,A2,'👷horas'!$E:$E,B2,'👷horas'!$F:$F,F2,'👷horas'!$G:$G,G2) -> 0 | L2: =I2/D2 -> 0.32627622 | M2: =IF(P2="TERMINADO",0,H2-(J2+K2)) -> 0 | N2: =1-(I2/H2) -> 0.16247651 | O2: =IF(NOT(ISNUMBER(H2)),0,IF(P2="Terminado",1,IF(J2=0,0,MIN(1,J2/H2)))) -> 1 | P2: Terminado | Q2: =IF(COUNTIFS(A:A,A2,P:P,"Terminado")=COUNTIF(A:A,A2),"Terminado",IF(COUNTIFS(A:A,A2,P:P,"En proceso")>0,"En proceso","Pendiente")) -> Terminado | R2: =IFERROR(__xludf.DUMMYFUNCTION("SPARKLINE(O2,{""charttype"",""bar"";""max"",1;""color1"",IF(P2=""Terminado"",""#4CAF50"",IF(O2>=0.5,""#FFA500"",""#F44336""))})"),"")
A3: Druni CC los alcores | B3: Gracos 2 | C3: BASTIDOR NORMAL 150 | D3: 50.54 | E3: 46080 | F3: Fabricación | G3: Ensamblaje | H3: =IFERROR(__xludf.DUMMYFUNCTION("(IFERROR(FILTER(BBDD!$J:$J,BBDD!$G:$G=C3,BBDD!$H:$H=F3,BBDD!$I:$I=G3),""NO TIENE PROCESO""))*D3"),54.04) -> 54.04 | I3: =J3+K3 -> 49.5 | J3: =SUMIFS('👷horas'!$J:$J,'👷horas'!$D:$D,A3,'👷horas'!$E:$E,B3,'👷horas'!$F:$F,F3,'👷horas'!$G:$G,G3) -> 37 | K3: =SUMIFS('👷horas'!$K:$K,'👷horas'!$D:$D,A3,'👷horas'!$E:$E,B3,'👷horas'!$F:$F,F3,'👷horas'!$G:$G,G3) -> 12.5 | L3: =I3/D3 -> 0.97942224 | M3: =IF(P3="TERMINADO",0,H3-(J3+K3)) -> 0 | N3: =1-(I3/H3) -> 0.084011843 | O3: =IF(NOT(ISNUMBER(H3)),0,IF(P3="Terminado",1,IF(J3=0,0,MIN(1,J3/H3)))) -> 1 | P3: Terminado | Q3: =IF(COUNTIFS(A:A,A3,P:P,"Terminado")=COUNTIF(A:A,A3),"Terminado",IF(COUNTIFS(A:A,A3,P:P,"En proceso")>0,"En proceso","Pendiente")) -> Terminado | R3: =IFERROR(__xludf.DUMMYFUNCTION("SPARKLINE(O3,{""charttype"",""bar"";""max"",1;""color1"",IF(P3=""Terminado"",""#4CAF50"",IF(O3>=0.5,""#FFA500"",""#F44336""))})"),"")
A4: Druni CC los alcores | B4: Gracos 2 | C4: BASTIDOR NORMAL 150 | D4: 50.54 | E4: 46080 | F4: Fabricación | G4: Colocación de perfiles | H4: =IFERROR(__xludf.DUMMYFUNCTION("(IFERROR(FILTER(BBDD!$J:$J,BBDD!$G:$G=C4,BBDD!$H:$H=F4,BBDD!$I:$I=G4),""NO TIENE PROCESO""))*D4"),10.108) -> 10.108 | I4: =J4+K4 -> 11.39 | J4: =SUMIFS('👷horas'!$J:$J,'👷horas'!$D:$D,A4,'👷horas'!$E:$E,B4,'👷horas'!$F:$F,F4,'👷horas'!$G:$G,G4) -> 11.39 | K4: =SUMIFS('👷horas'!$K:$K,'👷horas'!$D:$D,A4,'👷horas'!$E:$E,B4,'👷horas'!$F:$F,F4,'👷horas'!$G:$G,G4) -> 0 | L4: =I4/D4 -> 0.22536605 | M4: =IF(P4="TERMINADO",0,H4-(J4+K4)) -> 0 | N4: =1-(I4/H4) -> -0.12683023 | O4: =IF(NOT(ISNUMBER(H4)),0,IF(P4="Terminado",1,IF(J4=0,0,MIN(1,J4/H4)))) -> 1 | P4: Terminado | Q4: =IF(COUNTIFS(A:A,A4,P:P,"Terminado")=COUNTIF(A:A,A4),"Terminado",IF(COUNTIFS(A:A,A4,P:P,"En proceso")>0,"En proceso","Pendiente")) -> Terminado | R4: =IFERROR(__xludf.DUMMYFUNCTION("SPARKLINE(O4,{""charttype"",""bar"";""max"",1;""color1"",IF(P4=""Terminado"",""#4CAF50"",IF(O4>=0.5,""#FFA500"",""#F44336""))})"),"")
A5: Druni CC los alcores | B5: Gracos 2 | C5: BASTIDOR NORMAL 150 | D5: 50.54 | E5: 46080 | F5: Fabricación | G5: Embalaje/carga/descarga material | H5: =IFERROR(__xludf.DUMMYFUNCTION("(IFERROR(FILTER(BBDD!$J:$J,BBDD!$G:$G=C5,BBDD!$H:$H=F5,BBDD!$I:$I=G5),""NO TIENE PROCESO""))*D5"),8.081) -> 8.081 | I5: =J5+K5 -> 5.5 | J5: =SUMIFS('👷horas'!$J:$J,'👷horas'!$D:$D,A5,'👷horas'!$E:$E,B5,'👷horas'!$F:$F,F5,'👷horas'!$G:$G,G5) -> 5.5 | K5: =SUMIFS('👷horas'!$K:$K,'👷horas'!$D:$D,A5,'👷horas'!$E:$E,B5,'👷horas'!$F:$F,F5,'👷horas'!$G:$G,G5) -> 0 | L5: =I5/D5 -> 0.10882469 | M5: =IF(P5="TERMINADO",0,H5-(J5+K5)) -> 0 | N5: =1-(I5/H5) -> 0.31939116 | O5: =IF(NOT(ISNUMBER(H5)),0,IF(P5="Terminado",1,IF(J5=0,0,MIN(1,J5/H5)))) -> 1 | P5: Terminado | Q5: =IF(COUNTIFS(A:A,A5,P:P,"Terminado")=COUNTIF(A:A,A5),"Terminado",IF(COUNTIFS(A:A,A5,P:P,"En proceso")>0,"En proceso","Pendiente")) -> Terminado | R5: =IFERROR(__xludf.DUMMYFUNCTION("SPARKLINE(O5,{""charttype"",""bar"";""max"",1;""color1"",IF(P5=""Terminado"",""#4CAF50"",IF(O5>=0.5,""#FFA500"",""#F44336""))})"),"")
A6: Druni CC los alcores | B6: Gracos 2 | C6: BASTIDOR NORMAL 150 | D6: 50.54 | E6: 46080 | F6: Pintura | G6: Lijado y/o Masillado | H6: =IFERROR(__xludf.DUMMYFUNCTION("(IFERROR(FILTER(BBDD!$J:$J,BBDD!$G:$G=C6,BBDD!$H:$H=F6,BBDD!$I:$I=G6),""NO TIENE PROCESO""))*D6"),30.604497000000002) -> 30.604497 | I6: =J6+K6 -> 48.9025 | J6: =SUMIFS('👷horas'!$J:$J,'👷horas'!$D:$D,A6,'👷horas'!$E:$E,B6,'👷horas'!$F:$F,F6,'👷horas'!$G:$G,G6) -> 41.9025 | K6: =SUMIFS('👷horas'!$K:$K,'👷horas'!$D:$D,A6,'👷horas'!$E:$E,B6,'👷horas'!$F:$F,F6,'👷horas'!$G:$G,G6) -> 7 | L6: =I6/D6 -> 0.96759992 | M6: =IF(P6="TERMINADO",0,H6-(J6+K6)) -> 0 | N6: =1-(I6/H6) -> -0.59788609 | O6: =IF(NOT(ISNUMBER(H6)),0,IF(P6="Terminado",1,IF(J6=0,0,MIN(1,J6/H6)))) -> 1 | P6: Terminado | Q6: =IF(COUNTIFS(A:A,A6,P:P,"Terminado")=COUNTIF(A:A,A6),"Terminado",IF(COUNTIFS(A:A,A6,P:P,"En proceso")>0,"En proceso","Pendiente")) -> Terminado | R6: =IFERROR(__xludf.DUMMYFUNCTION("SPARKLINE(O6,{""charttype"",""bar"";""max"",1;""color1"",IF(P6=""Terminado"",""#4CAF50"",IF(O6>=0.5,""#FFA500"",""#F44336""))})"),"")
A7: Druni CC los alcores | B7: Gracos 2 | C7: BASTIDOR NORMAL 150 | D7: 50.54 | E7: 46080 | F7: Pintura | G7: Imprimación/Pintura | H7: =IFERROR(__xludf.DUMMYFUNCTION("(IFERROR(FILTER(BBDD!$J:$J,BBDD!$G:$G=C7,BBDD!$H:$H=F7,BBDD!$I:$I=G7),""NO TIENE PROCESO""))*D7"),26.45769) -> 26.45769 | I7: =J7+K7 -> 18.7 | J7: =SUMIFS('👷horas'!$J:$J,'👷horas'!$D:$D,A7,'👷horas'!$E:$E,B7,'👷horas'!$F:$F,F7,'👷horas'!$G:$G,G7) -> 11.7 | K7: =SUMIFS('👷horas'!$K:$K,'👷horas'!$D:$D,A7,'👷horas'!$E:$E,B7,'👷horas'!$F:$F,F7,'👷horas'!$G:$G,G7) -> 7 | L7: =I7/D7 -> 0.37000396 | M7: =IF(P7="TERMINADO",0,H7-(J7+K7)) -> 0 | N7: =1-(I7/H7) -> 0.29321116 | O7: =IF(NOT(ISNUMBER(H7)),0,IF(P7="Terminado",1,IF(J7=0,0,MIN(1,J7/H7)))) -> 1 | P7: Terminado | Q7: =IF(COUNTIFS(A:A,A7,P:P,"Terminado")=COUNTIF(A:A,A7),"Terminado",IF(COUNTIFS(A:A,A7,P:P,"En proceso")>0,"En proceso","Pendiente")) -> Terminado | R7: =IFERROR(__xludf.DUMMYFUNCTION("SPARKLINE(O7,{""charttype"",""bar"";""max"",1;""color1"",IF(P7=""Terminado"",""#4CAF50"",IF(O7>=0.5,""#FFA500"",""#F44336""))})"),"")
A8: Druni CC los alcores | B8: Gracos | C8: BASTIDOR NORMAL 100 | D8: 17.91 | E8: 46080 | F8: =IFERROR(__xludf.DUMMYFUNCTION("FILTER(BBDD!H:H,BBDD!G:G=C8)"),"CNC") -> CNC | G8: =IFERROR(__xludf.DUMMYFUNCTION("FILTER(BBDD!I:I,BBDD!G:G=C8)"),"CNC") -> CNC | H8: =IFERROR(__xludf.DUMMYFUNCTION("(IFERROR(FILTER(BBDD!$J:$J,BBDD!$G:$G=C8,BBDD!$H:$H=F8,BBDD!$I:$I=G8),""NO TIENE PROCESO""))*D8"),6.2684999999999995) -> 6.2685 | I8: =J8+K8 -> 6.3 | J8: =SUMIFS('👷horas'!$J:$J,'👷horas'!$D:$D,A8,'👷horas'!$E:$E,B8,'👷horas'!$F:$F,F8,'👷horas'!$G:$G,G8) -> 6.3 | K8: =SUMIFS('👷horas'!$K:$K,'👷horas'!$D:$D,A8,'👷horas'!$E:$E,B8,'👷horas'!$F:$F,F8,'👷horas'!$G:$G,G8) -> 0 | L8: =I8/D8 -> 0.35175879 | M8: =IF(P8="TERMINADO",0,H8-(J8+K8)) -> 0 | N8: =1-(I8/H8) -> -0.0050251256 | O8: =IF(NOT(ISNUMBER(H8)),0,IF(P8="Terminado",1,IF(J8=0,0,MIN(1,J8/H8)))) -> 1 | P8: Terminado | Q8: =IF(COUNTIFS(A:A,A8,P:P,"Terminado")=COUNTIF(A:A,A8),"Terminado",IF(COUNTIFS(A:A,A8,P:P,"En proceso")>0,"En proceso","Pendiente")) -> Terminado | R8: =IFERROR(__xludf.DUMMYFUNCTION("SPARKLINE(O8,{""charttype"",""bar"";""max"",1;""color1"",IF(P8=""Terminado"",""#4CAF50"",IF(O8>=0.5,""#FFA500"",""#F44336""))})"),"")
A9: Druni CC los alcores | B9: Gracos | C9: BASTIDOR NORMAL 100 | D9: 17.91 | E9: 46080 | F9: =IFERROR(__xludf.DUMMYFUNCTION("""COMPUTED_VALUE"""),"Fabricación") -> Fabricación | G9: =IFERROR(__xludf.DUMMYFUNCTION("""COMPUTED_VALUE"""),"Ensamblaje") -> Ensamblaje | H9: =IFERROR(__xludf.DUMMYFUNCTION("(IFERROR(FILTER(BBDD!$J:$J,BBDD!$G:$G=C9,BBDD!$H:$H=F9,BBDD!$I:$I=G9),""NO TIENE PROCESO""))*D9"),17.91) -> 17.91 | I9: =J9+K9 -> 18 | J9: =SUMIFS('👷horas'!$J:$J,'👷horas'!$D:$D,A9,'👷horas'!$E:$E,B9,'👷horas'!$F:$F,F9,'👷horas'!$G:$G,G9) -> 18 | K9: =SUMIFS('👷horas'!$K:$K,'👷horas'!$D:$D,A9,'👷horas'!$E:$E,B9,'👷horas'!$F:$F,F9,'👷horas'!$G:$G,G9) -> 0 | L9: =I9/D9 -> 1.0050251 | M9: =IF(P9="TERMINADO",0,H9-(J9+K9)) -> 0 | N9: =1-(I9/H9) -> -0.0050251256 | O9: =IF(NOT(ISNUMBER(H9)),0,IF(P9="Terminado",1,IF(J9=0,0,MIN(1,J9/H9)))) -> 1 | P9: Terminado | Q9: =IF(COUNTIFS(A:A,A9,P:P,"Terminado")=COUNTIF(A:A,A9),"Terminado",IF(COUNTIFS(A:A,A9,P:P,"En proceso")>0,"En proceso","Pendiente")) -> Terminado | R9: =IFERROR(__xludf.DUMMYFUNCTION("SPARKLINE(O9,{""charttype"",""bar"";""max"",1;""color1"",IF(P9=""Terminado"",""#4CAF50"",IF(O9>=0.5,""#FFA500"",""#F44336""))})"),"")
A10: Druni CC los alcores | B10: Gracos | C10: BASTIDOR NORMAL 100 | D10: 17.91 | E10: 46080 | F10: =IFERROR(__xludf.DUMMYFUNCTION("""COMPUTED_VALUE"""),"Fabricación") -> Fabricación | G10: =IFERROR(__xludf.DUMMYFUNCTION("""COMPUTED_VALUE"""),"Colocación de perfiles") -> Colocación de perfiles | H10: =IFERROR(__xludf.DUMMYFUNCTION("(IFERROR(FILTER(BBDD!$J:$J,BBDD!$G:$G=C10,BBDD!$H:$H=F10,BBDD!$I:$I=G10),""NO TIENE PROCESO""))*D10"),3.5820000000000003) -> 3.582 | I10: =J10+K10 -> 3.594 | J10: =SUMIFS('👷horas'!$J:$J,'👷horas'!$D:$D,A10,'👷horas'!$E:$E,B10,'👷horas'!$F:$F,F10,'👷horas'!$G:$G,G10) -> 3.594 | K10: =SUMIFS('👷horas'!$K:$K,'👷horas'!$D:$D,A10,'👷horas'!$E:$E,B10,'👷horas'!$F:$F,F10,'👷horas'!$G:$G,G10) -> 0 | L10: =I10/D10 -> 0.20067002 | M10: =IF(P10="TERMINADO",0,H10-(J10+K10)) -> 0 | N10: =1-(I10/H10) -> -0.0033500838 | O10: =IF(NOT(ISNUMBER(H10)),0,IF(P10="Terminado",1,IF(J10=0,0,MIN(1,J10/H10)))) -> 1 | P10: Terminado | Q10: =IF(COUNTIFS(A:A,A10,P:P,"Terminado")=COUNTIF(A:A,A10),"Terminado",IF(COUNTIFS(A:A,A10,P:P,"En proceso")>0,"En proceso","Pendiente")) -> Terminado | R10: =IFERROR(__xludf.DUMMYFUNCTION("SPARKLINE(O10,{""charttype"",""bar"";""max"",1;""color1"",IF(P10=""Terminado"",""#4CAF50"",IF(O10>=0.5,""#FFA500"",""#F44336""))})"),"")
A11: Druni CC los alcores | B11: Gracos | C11: BASTIDOR NORMAL 100 | D11: 17.91 | E11: 46080 | F11: =IFERROR(__xludf.DUMMYFUNCTION("""COMPUTED_VALUE"""),"Fabricación") -> Fabricación | G11: =IFERROR(__xludf.DUMMYFUNCTION("""COMPUTED_VALUE"""),"Embalaje/carga/descarga material") -> Embalaje/carga/descarga material | H11: =IFERROR(__xludf.DUMMYFUNCTION("(IFERROR(FILTER(BBDD!$J:$J,BBDD!$G:$G=C11,BBDD!$H:$H=F11,BBDD!$I:$I=G11),""NO TIENE PROCESO""))*D11"),2.6865) -> 2.6865 | I11: =J11+K11 -> 2.5 | J11: =SUMIFS('👷horas'!$J:$J,'👷horas'!$D:$D,A11,'👷horas'!$E:$E,B11,'👷horas'!$F:$F,F11,'👷horas'!$G:$G,G11) -> 2.5 | K11: =SUMIFS('👷horas'!$K:$K,'👷horas'!$D:$D,A11,'👷horas'!$E:$E,B11,'👷horas'!$F:$F,F11,'👷horas'!$G:$G,G11) -> 0 | L11: =I11/D11 -> 0.13958682 | M11: =IF(P11="TERMINADO",0,H11-(J11+K11)) -> 0 | N11: =1-(I11/H11) -> 0.06942118 | O11: =IF(NOT(ISNUMBER(H11)),0,IF(P11="Terminado",1,IF(J11=0,0,MIN(1,J11/H11)))) -> 1 | P11: Terminado | Q11: =IF(COUNTIFS(A:A,A11,P:P,"Terminado")=COUNTIF(A:A,A11),"Terminado",IF(COUNTIFS(A:A,A11,P:P,"En proceso")>0,"En proceso","Pendiente")) -> Terminado | R11: =IFERROR(__xludf.DUMMYFUNCTION("SPARKLINE(O11,{""charttype"",""bar"";""max"",1;""color1"",IF(P11=""Terminado"",""#4CAF50"",IF(O11>=0.5,""#FFA500"",""#F44336""))})"),"")
A12: Druni CC los alcores | B12: Gracos | C12: BASTIDOR NORMAL 100 | D12: 17.91 | E12: 46080 | F12: =IFERROR(__xludf.DUMMYFUNCTION("""COMPUTED_VALUE"""),"Pintura") -> Pintura | G12: =IFERROR(__xludf.DUMMYFUNCTION("""COMPUTED_VALUE"""),"Lijado y/o Masillado") -> Lijado y/o Masillado | H12: =IFERROR(__xludf.DUMMYFUNCTION("(IFERROR(FILTER(BBDD!$J:$J,BBDD!$G:$G=C12,BBDD!$H:$H=F12,BBDD!$I:$I=G12),""NO TIENE PROCESO""))*D12"),10.746) -> 10.746 | I12: =J12+K12 -> 16.5975 | J12: =SUMIFS('👷horas'!$J:$J,'👷horas'!$D:$D,A12,'👷horas'!$E:$E,B12,'👷horas'!$F:$F,F12,'👷horas'!$G:$G,G12) -> 16.5975 | K12: =SUMIFS('👷horas'!$K:$K,'👷horas'!$D:$D,A12,'👷horas'!$E:$E,B12,'👷horas'!$F:$F,F12,'👷horas'!$G:$G,G12) -> 0 | L12: =I12/D12 -> 0.92671692 | M12: =IF(P12="TERMINADO",0,H12-(J12+K12)) -> 0 | N12: =1-(I12/H12) -> -0.5445282 | O12: =IF(NOT(ISNUMBER(H12)),0,IF(P12="Terminado",1,IF(J12=0,0,MIN(1,J12/H12)))) -> 1 | P12: Terminado | Q12: =IF(COUNTIFS(A:A,A12,P:P,"Terminado")=COUNTIF(A:A,A12),"Terminado",IF(COUNTIFS(A:A,A12,P:P,"En proceso")>0,"En proceso","Pendiente")) -> Terminado | R12: =IFERROR(__xludf.DUMMYFUNCTION("SPARKLINE(O12,{""charttype"",""bar"";""max"",1;""color1"",IF(P12=""Terminado"",""#4CAF50"",IF(O12>=0.5,""#FFA500"",""#F44336""))})"),"")
A13: Druni CC los alcores | B13: Gracos | C13: BASTIDOR NORMAL 100 | D13: 17.91 | E13: 46080 | F13: =IFERROR(__xludf.DUMMYFUNCTION("""COMPUTED_VALUE"""),"Pintura") -> Pintura | G13: =IFERROR(__xludf.DUMMYFUNCTION("""COMPUTED_VALUE"""),"Imprimación/Pintura") -> Imprimación/Pintura | H13: =IFERROR(__xludf.DUMMYFUNCTION("(IFERROR(FILTER(BBDD!$J:$J,BBDD!$G:$G=C13,BBDD!$H:$H=F13,BBDD!$I:$I=G13),""NO TIENE PROCESO""))*D13"),8.955) -> 8.955 | I13: =J13+K13 -> 9 | J13: =SUMIFS('👷horas'!$J:$J,'👷horas'!$D:$D,A13,'👷horas'!$E:$E,B13,'👷horas'!$F:$F,F13,'👷horas'!$G:$G,G13) -> 9 | K13: =SUMIFS('👷horas'!$K:$K,'👷horas'!$D:$D,A13,'👷horas'!$E:$E,B13,'👷horas'!$F:$F,F13,'👷horas'!$G:$G,G13) -> 0 | L13: =I13/D13 -> 0.50251256 | M13: =IF(P13="TERMINADO",0,H13-(J13+K13)) -> 0 | N13: =1-(I13/H13) -> -0.0050251256 | O13: =IF(NOT(ISNUMBER(H13)),0,IF(P13="Terminado",1,IF(J13=0,0,MIN(1,J13/H13)))) -> 1 | P13: Terminado | Q13: =IF(COUNTIFS(A:A,A13,P:P,"Terminado")=COUNTIF(A:A,A13),"Terminado",IF(COUNTIFS(A:A,A13,P:P,"En proceso")>0,"En proceso","Pendiente")) -> Terminado | R13: =IFERROR(__xludf.DUMMYFUNCTION("SPARKLINE(O13,{""charttype"",""bar"";""max"",1;""color1"",IF(P13=""Terminado"",""#4CAF50"",IF(O13>=0.5,""#FFA500"",""#F44336""))})"),"")
A14: Druni Parc Central | B14: Cruz | C14: BASTIDOR DE TABICA 150X12 | D14: 17.5 | E14: 46084 | F14: =IFERROR(__xludf.DUMMYFUNCTION("FILTER(BBDD!H:H,BBDD!G:G=C14)"),"CNC") -> CNC | G14: =IFERROR(__xludf.DUMMYFUNCTION("FILTER(BBDD!I:I,BBDD!G:G=C14)"),"CNC") -> CNC | H14: =IFERROR(__xludf.DUMMYFUNCTION("(IFERROR(FILTER(BBDD!$J:$J,BBDD!$G:$G=C14,BBDD!$H:$H=F14,BBDD!$I:$I=G14),""NO TIENE PROCESO""))*D14"),3.5) -> 3.5 | I14: =J14+K14 -> 1.5 | J14: =SUMIFS('👷horas'!$J:$J,'👷horas'!$D:$D,A14,'👷horas'!$E:$E,B14,'👷horas'!$F:$F,F14,'👷horas'!$G:$G,G14) -> 1.5 | K14: =SUMIFS('👷horas'!$K:$K,'👷horas'!$D:$D,A14,'👷horas'!$E:$E,B14,'👷horas'!$F:$F,F14,'👷horas'!$G:$G,G14) -> 0 | L14: =I14/D14 -> 0.085714286 | M14: =IF(P14="TERMINADO",0,H14-(J14+K14)) -> 0 | N14: =1-(I14/H14) -> 0.57142857 | O14: =IF(NOT(ISNUMBER(H14)),0,IF(P14="Terminado",1,IF(J14=0,0,MIN(1,J14/H14)))) -> 1 | P14: Terminado | Q14: =IF(COUNTIFS(A:A,A14,P:P,"Terminado")=COUNTIF(A:A,A14),"Terminado",IF(COUNTIFS(A:A,A14,P:P,"En proceso")>0,"En proceso","Pendiente")) -> Terminado | R14: =IFERROR(__xludf.DUMMYFUNCTION("SPARKLINE(O14,{""charttype"",""bar"";""max"",1;""color1"",IF(P14=""Terminado"",""#4CAF50"",IF(O14>=0.5,""#FFA500"",""#F44336""))})"),"")
A15: Druni Parc Central | B15: Cruz | C15: BASTIDOR DE TABICA 150X12 | D15: 17.5 | E15: 46084 | F15: =IFERROR(__xludf.DUMMYFUNCTION("""COMPUTED_VALUE"""),"Fabricación") -> Fabricación | G15: =IFERROR(__xludf.DUMMYFUNCTION("""COMPUTED_VALUE"""),"Ensamblaje") -> Ensamblaje | H15: =IFERROR(__xludf.DUMMYFUNCTION("(IFERROR(FILTER(BBDD!$J:$J,BBDD!$G:$G=C15,BBDD!$H:$H=F15,BBDD!$I:$I=G15),""NO TIENE PROCESO""))*D15"),10.85) -> 10.85 | I15: =J15+K15 -> 11.75 | J15: =SUMIFS('👷horas'!$J:$J,'👷horas'!$D:$D,A15,'👷horas'!$E:$E,B15,'👷horas'!$F:$F,F15,'👷horas'!$G:$G,G15) -> 11.75 | K15: =SUMIFS('👷horas'!$K:$K,'👷horas'!$D:$D,A15,'👷horas'!$E:$E,B15,'👷horas'!$F:$F,F15,'👷horas'!$G:$G,G15) -> 0 | L15: =I15/D15 -> 0.67142857 | M15: =IF(P15="TERMINADO",0,H15-(J15+K15)) -> 0 | N15: =1-(I15/H15) -> -0.082949309 | O15: =IF(NOT(ISNUMBER(H15)),0,IF(P15="Terminado",1,IF(J15=0,0,MIN(1,J15/H15)))) -> 1 | P15: Terminado | Q15: =IF(COUNTIFS(A:A,A15,P:P,"Terminado")=COUNTIF(A:A,A15),"Terminado",IF(COUNTIFS(A:A,A15,P:P,"En proceso")>0,"En proceso","Pendiente")) -> Terminado | R15: =IFERROR(__xludf.DUMMYFUNCTION("SPARKLINE(O15,{""charttype"",""bar"";""max"",1;""color1"",IF(P15=""Terminado"",""#4CAF50"",IF(O15>=0.5,""#FFA500"",""#F44336""))})"),"")
A16: Druni Parc Central | B16: Cruz | C16: BASTIDOR DE TABICA 150X12 | D16: 17.5 | E16: 46084 | F16: =IFERROR(__xludf.DUMMYFUNCTION("""COMPUTED_VALUE"""),"Fabricación") -> Fabricación | G16: =IFERROR(__xludf.DUMMYFUNCTION("""COMPUTED_VALUE"""),"Colocación de perfiles") -> Colocación de perfiles | H16: =IFERROR(__xludf.DUMMYFUNCTION("(IFERROR(FILTER(BBDD!$J:$J,BBDD!$G:$G=C16,BBDD!$H:$H=F16,BBDD!$I:$I=G16),""NO TIENE PROCESO""))*D16"),3.5) -> 3.5 | I16: =J16+K16 -> 5.5 | J16: =SUMIFS('👷horas'!$J:$J,'👷horas'!$D:$D,A16,'👷horas'!$E:$E,B16,'👷horas'!$F:$F,F16,'👷horas'!$G:$G,G16) -> 5.5 | K16: =SUMIFS('👷horas'!$K:$K,'👷horas'!$D:$D,A16,'👷horas'!$E:$E,B16,'👷horas'!$F:$F,F16,'👷horas'!$G:$G,G16) -> 0 | L16: =I16/D16 -> 0.31428571 | M16: =IF(P16="TERMINADO",0,H16-(J16+K16)) -> 0 | N16: =1-(I16/H16) -> -0.57142857 | O16: =IF(NOT(ISNUMBER(H16)),0,IF(P16="Terminado",1,IF(J16=0,0,MIN(1,J16/H16)))) -> 1 | P16: Terminado | Q16: =IF(COUNTIFS(A:A,A16,P:P,"Terminado")=COUNTIF(A:A,A16),"Terminado",IF(COUNTIFS(A:A,A16,P:P,"En proceso")>0,"En proceso","Pendiente")) -> Terminado | R16: =IFERROR(__xludf.DUMMYFUNCTION("SPARKLINE(O16,{""charttype"",""bar"";""max"",1;""color1"",IF(P16=""Terminado"",""#4CAF50"",IF(O16>=0.5,""#FFA500"",""#F44336""))})"),"")
A17: Druni Parc Central | B17: Cruz | C17: BASTIDOR DE TABICA 150X12 | D17: 17.5 | E17: 46084 | F17: =IFERROR(__xludf.DUMMYFUNCTION("""COMPUTED_VALUE"""),"Fabricación") -> Fabricación | G17: =IFERROR(__xludf.DUMMYFUNCTION("""COMPUTED_VALUE"""),"Embalaje/carga/descarga material") -> Embalaje/carga/descarga material | H17: =IFERROR(__xludf.DUMMYFUNCTION("(IFERROR(FILTER(BBDD!$J:$J,BBDD!$G:$G=C17,BBDD!$H:$H=F17,BBDD!$I:$I=G17),""NO TIENE PROCESO""))*D17"),2.625) -> 2.625 | I17: =J17+K17 -> 2 | J17: =SUMIFS('👷horas'!$J:$J,'👷horas'!$D:$D,A17,'👷horas'!$E:$E,B17,'👷horas'!$F:$F,F17,'👷horas'!$G:$G,G17) -> 2 | K17: =SUMIFS('👷horas'!$K:$K,'👷horas'!$D:$D,A17,'👷horas'!$E:$E,B17,'👷horas'!$F:$F,F17,'👷horas'!$G:$G,G17) -> 0 | L17: =I17/D17 -> 0.11428571 | M17: =IF(P17="TERMINADO",0,H17-(J17+K17)) -> 0 | N17: =1-(I17/H17) -> 0.23809524 | O17: =IF(NOT(ISNUMBER(H17)),0,IF(P17="Terminado",1,IF(J17=0,0,MIN(1,J17/H17)))) -> 1 | P17: Terminado | Q17: =IF(COUNTIFS(A:A,A17,P:P,"Terminado")=COUNTIF(A:A,A17),"Terminado",IF(COUNTIFS(A:A,A17,P:P,"En proceso")>0,"En proceso","Pendiente")) -> Terminado | R17: =IFERROR(__xludf.DUMMYFUNCTION("SPARKLINE(O17,{""charttype"",""bar"";""max"",1;""color1"",IF(P17=""Terminado"",""#4CAF50"",IF(O17>=0.5,""#FFA500"",""#F44336""))})"),"")
A18: Druni Parc Central | B18: Cruz | C18: BASTIDOR DE TABICA 150X12 | D18: 17.5 | E18: 46084 | F18: =IFERROR(__xludf.DUMMYFUNCTION("""COMPUTED_VALUE"""),"Pintura") -> Pintura | G18: =IFERROR(__xludf.DUMMYFUNCTION("""COMPUTED_VALUE"""),"Lijado y/o Masillado") -> Lijado y/o Masillado | H18: =IFERROR(__xludf.DUMMYFUNCTION("(IFERROR(FILTER(BBDD!$J:$J,BBDD!$G:$G=C18,BBDD!$H:$H=F18,BBDD!$I:$I=G18),""NO TIENE PROCESO""))*D18"),8.75) -> 8.75 | I18: =J18+K18 -> 19.5 | J18: =SUMIFS('👷horas'!$J:$J,'👷horas'!$D:$D,A18,'👷horas'!$E:$E,B18,'👷horas'!$F:$F,F18,'👷horas'!$G:$G,G18) -> 18 | K18: =SUMIFS('👷horas'!$K:$K,'👷horas'!$D:$D,A18,'👷horas'!$E:$E,B18,'👷horas'!$F:$F,F18,'👷horas'!$G:$G,G18) -> 1.5 | L18: =I18/D18 -> 1.1142857 | M18: =IF(P18="TERMINADO",0,H18-(J18+K18)) -> 0 | N18: =1-(I18/H18) -> -1.2285714 | O18: =IF(NOT(ISNUMBER(H18)),0,IF(P18="Terminado",1,IF(J18=0,0,MIN(1,J18/H18)))) -> 1 | P18: Terminado | Q18: =IF(COUNTIFS(A:A,A18,P:P,"Terminado")=COUNTIF(A:A,A18),"Terminado",IF(COUNTIFS(A:A,A18,P:P,"En proceso")>0,"En proceso","Pendiente")) -> Terminado | R18: =IFERROR(__xludf.DUMMYFUNCTION("SPARKLINE(O18,{""charttype"",""bar"";""max"",1;""color1"",IF(P18=""Terminado"",""#4CAF50"",IF(O18>=0.5,""#FFA500"",""#F44336""))})"),"")
A19: Druni Parc Central | B19: Cruz | C19: BASTIDOR DE TABICA 150X12 | D19: 17.5 | E19: 46084 | F19: =IFERROR(__xludf.DUMMYFUNCTION("""COMPUTED_VALUE"""),"Pintura") -> Pintura | G19: =IFERROR(__xludf.DUMMYFUNCTION("""COMPUTED_VALUE"""),"Imprimación/Pintura") -> Imprimación/Pintura | H19: =IFERROR(__xludf.DUMMYFUNCTION("(IFERROR(FILTER(BBDD!$J:$J,BBDD!$G:$G=C19,BBDD!$H:$H=F19,BBDD!$I:$I=G19),""NO TIENE PROCESO""))*D19"),7.0) -> 7 | I19: =J19+K19 -> 6.3 | J19: =SUMIFS('👷horas'!$J:$J,'👷horas'!$D:$D,A19,'👷horas'!$E:$E,B19,'👷horas'!$F:$F,F19,'👷horas'!$G:$G,G19) -> 6.3 | K19: =SUMIFS('👷horas'!$K:$K,'👷horas'!$D:$D,A19,'👷horas'!$E:$E,B19,'👷horas'!$F:$F,F19,'👷horas'!$G:$G,G19) -> 0 | L19: =I19/D19 -> 0.36 | M19: =IF(P19="TERMINADO",0,H19-(J19+K19)) -> 0 | N19: =1-(I19/H19) -> 0.1 | O19: =IF(NOT(ISNUMBER(H19)),0,IF(P19="Terminado",1,IF(J19=0,0,MIN(1,J19/H19)))) -> 1 | P19: Terminado | Q19: =IF(COUNTIFS(A:A,A19,P:P,"Terminado")=COUNTIF(A:A,A19),"Terminado",IF(COUNTIFS(A:A,A19,P:P,"En proceso")>0,"En proceso","Pendiente")) -> Terminado | R19: =IFERROR(__xludf.DUMMYFUNCTION("SPARKLINE(O19,{""charttype"",""bar"";""max"",1;""color1"",IF(P19=""Terminado"",""#4CAF50"",IF(O19>=0.5,""#FFA500"",""#F44336""))})"),"")
A20: Druni Parc Central | B20: Ameba | C20: BASTIDOR DE TABICA CURVA 150X12 | D20: 13.7 | E20: 46084 | F20: =IFERROR(__xludf.DUMMYFUNCTION("FILTER(BBDD!H:H,BBDD!G:G=C20)"),"CNC") -> CNC | G20: =IFERROR(__xludf.DUMMYFUNCTION("FILTER(BBDD!I:I,BBDD!G:G=C20)"),"CNC") -> CNC | H20: =IFERROR(__xludf.DUMMYFUNCTION("(IFERROR(FILTER(BBDD!$J:$J,BBDD!$G:$G=C20,BBDD!$H:$H=F20,BBDD!$I:$I=G20),""NO TIENE PROCESO""))*D20"),2.74) -> 2.74 | I20: =J20+K20 -> 1 | J20: =SUMIFS('👷horas'!$J:$J,'👷horas'!$D:$D,A20,'👷horas'!$E:$E,B20,'👷horas'!$F:$F,F20,'👷horas'!$G:$G,G20) -> 1 | K20: =SUMIFS('👷horas'!$K:$K,'👷horas'!$D:$D,A20,'👷horas'!$E:$E,B20,'👷horas'!$F:$F,F20,'👷horas'!$G:$G,G20) -> 0 | L20: =I20/D20 -> 0.072992701 | M20: =IF(P20="TERMINADO",0,H20-(J20+K20)) -> 0 | N20: =1-(I20/H20) -> 0.6350365 | O20: =IF(NOT(ISNUMBER(H20)),0,IF(P20="Terminado",1,IF(J20=0,0,MIN(1,J20/H20)))) -> 1 | P20: Terminado | Q20: =IF(COUNTIFS(A:A,A20,P:P,"Terminado")=COUNTIF(A:A,A20),"Terminado",IF(COUNTIFS(A:A,A20,P:P,"En proceso")>0,"En proceso","Pendiente")) -> Terminado | R20: =IFERROR(__xludf.DUMMYFUNCTION("SPARKLINE(O20,{""charttype"",""bar"";""max"",1;""color1"",IF(P20=""Terminado"",""#4CAF50"",IF(O20>=0.5,""#FFA500"",""#F44336""))})"),"")
A21: Druni Parc Central | B21: Ameba | C21: BASTIDOR DE TABICA CURVA 150X12 | D21: 13.7 | E21: 46084 | F21: =IFERROR(__xludf.DUMMYFUNCTION("""COMPUTED_VALUE"""),"Fabricación") -> Fabricación | G21: =IFERROR(__xludf.DUMMYFUNCTION("""COMPUTED_VALUE"""),"Ensamblaje") -> Ensamblaje | H21: =IFERROR(__xludf.DUMMYFUNCTION("(IFERROR(FILTER(BBDD!$J:$J,BBDD!$G:$G=C21,BBDD!$H:$H=F21,BBDD!$I:$I=G21),""NO TIENE PROCESO""))*D21"),10.823) -> 10.823 | I21: =J21+K21 -> 11.5 | J21: =SUMIFS('👷horas'!$J:$J,'👷horas'!$D:$D,A21,'👷horas'!$E:$E,B21,'👷horas'!$F:$F,F21,'👷horas'!$G:$G,G21) -> 11.5 | K21: =SUMIFS('👷horas'!$K:$K,'👷horas'!$D:$D,A21,'👷horas'!$E:$E,B21,'👷horas'!$F:$F,F21,'👷horas'!$G:$G,G21) -> 0 | L21: =I21/D21 -> 0.83941606 | M21: =IF(P21="TERMINADO",0,H21-(J21+K21)) -> 0 | N21: =1-(I21/H21) -> -0.062551973 | O21: =IF(NOT(ISNUMBER(H21)),0,IF(P21="Terminado",1,IF(J21=0,0,MIN(1,J21/H21)))) -> 1 | P21: Terminado | Q21: =IF(COUNTIFS(A:A,A21,P:P,"Terminado")=COUNTIF(A:A,A21),"Terminado",IF(COUNTIFS(A:A,A21,P:P,"En proceso")>0,"En proceso","Pendiente")) -> Terminado | R21: =IFERROR(__xludf.DUMMYFUNCTION("SPARKLINE(O21,{""charttype"",""bar"";""max"",1;""color1"",IF(P21=""Terminado"",""#4CAF50"",IF(O21>=0.5,""#FFA500"",""#F44336""))})"),"")
A22: Druni Parc Central | B22: Ameba | C22: BASTIDOR DE TABICA CURVA 150X12 | D22: 13.7 | E22: 46084 | F22: =IFERROR(__xludf.DUMMYFUNCTION("""COMPUTED_VALUE"""),"Fabricación") -> Fabricación | G22: =IFERROR(__xludf.DUMMYFUNCTION("""COMPUTED_VALUE"""),"Colocación de perfiles") -> Colocación de perfiles | H22: =IFERROR(__xludf.DUMMYFUNCTION("(IFERROR(FILTER(BBDD!$J:$J,BBDD!$G:$G=C22,BBDD!$H:$H=F22,BBDD!$I:$I=G22),""NO TIENE PROCESO""))*D22"),2.74) -> 2.74 | I22: =J22+K22 -> 8.5 | J22: =SUMIFS('👷horas'!$J:$J,'👷horas'!$D:$D,A22,'👷horas'!$E:$E,B22,'👷horas'!$F:$F,F22,'👷horas'!$G:$G,G22) -> 8.5 | K22: =SUMIFS('👷horas'!$K:$K,'👷horas'!$D:$D,A22,'👷horas'!$E:$E,B22,'👷horas'!$F:$F,F22,'👷horas'!$G:$G,G22) -> 0 | L22: =I22/D22 -> 0.62043796 | M22: =IF(P22="TERMINADO",0,H22-(J22+K22)) -> 0 | N22: =1-(I22/H22) -> -2.1021898 | O22: =IF(NOT(ISNUMBER(H22)),0,IF(P22="Terminado",1,IF(J22=0,0,MIN(1,J22/H22)))) -> 1 | P22: Terminado | Q22: =IF(COUNTIFS(A:A,A22,P:P,"Terminado")=COUNTIF(A:A,A22),"Terminado",IF(COUNTIFS(A:A,A22,P:P,"En proceso")>0,"En proceso","Pendiente")) -> Terminado | R22: =IFERROR(__xludf.DUMMYFUNCTION("SPARKLINE(O22,{""charttype"",""bar"";""max"",1;""color1"",IF(P22=""Terminado"",""#4CAF50"",IF(O22>=0.5,""#FFA500"",""#F44336""))})"),"")
A23: Druni Parc Central | B23: Ameba | C23: BASTIDOR DE TABICA CURVA 150X12 | D23: 13.7 | E23: 46084 | F23: =IFERROR(__xludf.DUMMYFUNCTION("""COMPUTED_VALUE"""),"Fabricación") -> Fabricación | G23: =IFERROR(__xludf.DUMMYFUNCTION("""COMPUTED_VALUE"""),"Embalaje/carga/descarga material") -> Embalaje/carga/descarga material | H23: =IFERROR(__xludf.DUMMYFUNCTION("(IFERROR(FILTER(BBDD!$J:$J,BBDD!$G:$G=C23,BBDD!$H:$H=F23,BBDD!$I:$I=G23),""NO TIENE PROCESO""))*D23"),2.0549999999999997) -> 2.055 | I23: =J23+K23 -> 0.1 | J23: =SUMIFS('👷horas'!$J:$J,'👷horas'!$D:$D,A23,'👷horas'!$E:$E,B23,'👷horas'!$F:$F,F23,'👷horas'!$G:$G,G23) -> 0.1 | K23: =SUMIFS('👷horas'!$K:$K,'👷horas'!$D:$D,A23,'👷horas'!$E:$E,B23,'👷horas'!$F:$F,F23,'👷horas'!$G:$G,G23) -> 0 | L23: =I23/D23 -> 0.0072992701 | M23: =IF(P23="TERMINADO",0,H23-(J23+K23)) -> 0 | N23: =1-(I23/H23) -> 0.9513382 | O23: =IF(NOT(ISNUMBER(H23)),0,IF(P23="Terminado",1,IF(J23=0,0,MIN(1,J23/H23)))) -> 1 | P23: Terminado | Q23: =IF(COUNTIFS(A:A,A23,P:P,"Terminado")=COUNTIF(A:A,A23),"Terminado",IF(COUNTIFS(A:A,A23,P:P,"En proceso")>0,"En proceso","Pendiente")) -> Terminado | R23: =IFERROR(__xludf.DUMMYFUNCTION("SPARKLINE(O23,{""charttype"",""bar"";""max"",1;""color1"",IF(P23=""Terminado"",""#4CAF50"",IF(O23>=0.5,""#FFA500"",""#F44336""))})"),"")
A24: Druni Parc Central | B24: Ameba | C24: BASTIDOR DE TABICA CURVA 150X12 | D24: 13.7 | E24: 46084 | F24: =IFERROR(__xludf.DUMMYFUNCTION("""COMPUTED_VALUE"""),"Pintura") -> Pintura | G24: =IFERROR(__xludf.DUMMYFUNCTION("""COMPUTED_VALUE"""),"Lijado y/o Masillado") -> Lijado y/o Masillado | H24: =IFERROR(__xludf.DUMMYFUNCTION("(IFERROR(FILTER(BBDD!$J:$J,BBDD!$G:$G=C24,BBDD!$H:$H=F24,BBDD!$I:$I=G24),""NO TIENE PROCESO""))*D24"),8.219999999999999) -> 8.22 | I24: =J24+K24 -> 11 | J24: =SUMIFS('👷horas'!$J:$J,'👷horas'!$D:$D,A24,'👷horas'!$E:$E,B24,'👷horas'!$F:$F,F24,'👷horas'!$G:$G,G24) -> 11 | K24: =SUMIFS('👷horas'!$K:$K,'👷horas'!$D:$D,A24,'👷horas'!$E:$E,B24,'👷horas'!$F:$F,F24,'👷horas'!$G:$G,G24) -> 0 | L24: =I24/D24 -> 0.80291971 | M24: =IF(P24="TERMINADO",0,H24-(J24+K24)) -> 0 | N24: =1-(I24/H24) -> -0.33819951 | O24: =IF(NOT(ISNUMBER(H24)),0,IF(P24="Terminado",1,IF(J24=0,0,MIN(1,J24/H24)))) -> 1 | P24: Terminado | Q24: =IF(COUNTIFS(A:A,A24,P:P,"Terminado")=COUNTIF(A:A,A24),"Terminado",IF(COUNTIFS(A:A,A24,P:P,"En proceso")>0,"En proceso","Pendiente")) -> Terminado | R24: =IFERROR(__xludf.DUMMYFUNCTION("SPARKLINE(O24,{""charttype"",""bar"";""max"",1;""color1"",IF(P24=""Terminado"",""#4CAF50"",IF(O24>=0.5,""#FFA500"",""#F44336""))})"),"")
A25: Druni Parc Central | B25: Ameba | C25: BASTIDOR DE TABICA CURVA 150X12 | D25: 13.7 | E25: 46084 | F25: =IFERROR(__xludf.DUMMYFUNCTION("""COMPUTED_VALUE"""),"Pintura") -> Pintura | G25: =IFERROR(__xludf.DUMMYFUNCTION("""COMPUTED_VALUE"""),"Imprimación/Pintura") -> Imprimación/Pintura | H25: =IFERROR(__xludf.DUMMYFUNCTION("(IFERROR(FILTER(BBDD!$J:$J,BBDD!$G:$G=C25,BBDD!$H:$H=F25,BBDD!$I:$I=G25),""NO TIENE PROCESO""))*D25"),5.48) -> 5.48 | I25: =J25+K25 -> 4 | J25: =SUMIFS('👷horas'!$J:$J,'👷horas'!$D:$D,A25,'👷horas'!$E:$E,B25,'👷horas'!$F:$F,F25,'👷horas'!$G:$G,G25) -> 4 | K25: =SUMIFS('👷horas'!$K:$K,'👷horas'!$D:$D,A25,'👷horas'!$E:$E,B25,'👷horas'!$F:$F,F25,'👷horas'!$G:$G,G25) -> 0 | L25: =I25/D25 -> 0.2919708 | M25: =IF(P25="TERMINADO",0,H25-(J25+K25)) -> 0 | N25: =1-(I25/H25) -> 0.27007299 | O25: =IF(NOT(ISNUMBER(H25)),0,IF(P25="Terminado",1,IF(J25=0,0,MIN(1,J25/H25)))) -> 1 | P25: Terminado | Q25: =IF(COUNTIFS(A:A,A25,P:P,"Terminado")=COUNTIF(A:A,A25),"Terminado",IF(COUNTIFS(A:A,A25,P:P,"En proceso")>0,"En proceso","Pendiente")) -> Terminado | R25: =IFERROR(__xludf.DUMMYFUNCTION("SPARKLINE(O25,{""charttype"",""bar"";""max"",1;""color1"",IF(P25=""Terminado"",""#4CAF50"",IF(O25>=0.5,""#FFA500"",""#F44336""))})"),"")
A26: Druni Parc Central | B26: Hair | C26: HAIR - ESPEJO | D26: 12.24 | E26: 46084 | F26: =IFERROR(__xludf.DUMMYFUNCTION("FILTER(BBDD!H:H,BBDD!G:G=C26)"),"Fabricación") -> Fabricación | G26: =IFERROR(__xludf.DUMMYFUNCTION("FILTER(BBDD!I:I,BBDD!G:G=C26)"),"Pegado de composite/chapa") -> Pegado de composite/chapa | H26: =IFERROR(__xludf.DUMMYFUNCTION("(IFERROR(FILTER(BBDD!$J:$J,BBDD!$G:$G=C26,BBDD!$H:$H=F26,BBDD!$I:$I=G26),""NO TIENE PROCESO""))*D26"),6.364800000000001) -> 6.3648 | I26: =J26+K26 -> 0 | J26: =SUMIFS('👷horas'!$J:$J,'👷horas'!$D:$D,A26,'👷horas'!$E:$E,B26,'👷horas'!$F:$F,F26,'👷horas'!$G:$G,G26) -> 0 | K26: =SUMIFS('👷horas'!$K:$K,'👷horas'!$D:$D,A26,'👷horas'!$E:$E,B26,'👷horas'!$F:$F,F26,'👷horas'!$G:$G,G26) -> 0 | L26: =I26/D26 -> 0 | M26: =IF(P26="TERMINADO",0,H26-(J26+K26)) -> 0 | N26: =1-(I26/H26) -> 1 | O26: =IF(NOT(ISNUMBER(H26)),0,IF(P26="Terminado",1,IF(J26=0,0,MIN(1,J26/H26)))) -> 1 | P26: Terminado | Q26: =IF(COUNTIFS(A:A,A26,P:P,"Terminado")=COUNTIF(A:A,A26),"Terminado",IF(COUNTIFS(A:A,A26,P:P,"En proceso")>0,"En proceso","Pendiente")) -> Terminado | R26: =IFERROR(__xludf.DUMMYFUNCTION("SPARKLINE(O26,{""charttype"",""bar"";""max"",1;""color1"",IF(P26=""Terminado"",""#4CAF50"",IF(O26>=0.5,""#FFA500"",""#F44336""))})"),"")
A27: Druni Parc Central | B27: Hair | C27: HAIR - ESPEJO | D27: 12.24 | E27: 46084 | F27: =IFERROR(__xludf.DUMMYFUNCTION("""COMPUTED_VALUE"""),"Fabricación") -> Fabricación | G27: =IFERROR(__xludf.DUMMYFUNCTION("""COMPUTED_VALUE"""),"Embalaje/carga/descarga material") -> Embalaje/carga/descarga material | H27: =IFERROR(__xludf.DUMMYFUNCTION("(IFERROR(FILTER(BBDD!$J:$J,BBDD!$G:$G=C27,BBDD!$H:$H=F27,BBDD!$I:$I=G27),""NO TIENE PROCESO""))*D27"),5.6304) -> 5.6304 | I27: =J27+K27 -> 1 | J27: =SUMIFS('👷horas'!$J:$J,'👷horas'!$D:$D,A27,'👷horas'!$E:$E,B27,'👷horas'!$F:$F,F27,'👷horas'!$G:$G,G27) -> 0 | K27: =SUMIFS('👷horas'!$K:$K,'👷horas'!$D:$D,A27,'👷horas'!$E:$E,B27,'👷horas'!$F:$F,F27,'👷horas'!$G:$G,G27) -> 1 | L27: =I27/D27 -> 0.081699346 | M27: =IF(P27="TERMINADO",0,H27-(J27+K27)) -> 0 | N27: =1-(I27/H27) -> 0.82239273 | O27: =IF(NOT(ISNUMBER(H27)),0,IF(P27="Terminado",1,IF(J27=0,0,MIN(1,J27/H27)))) -> 1 | P27: Terminado | Q27: =IF(COUNTIFS(A:A,A27,P:P,"Terminado")=COUNTIF(A:A,A27),"Terminado",IF(COUNTIFS(A:A,A27,P:P,"En proceso")>0,"En proceso","Pendiente")) -> Terminado | R27: =IFERROR(__xludf.DUMMYFUNCTION("SPARKLINE(O27,{""charttype"",""bar"";""max"",1;""color1"",IF(P27=""Terminado"",""#4CAF50"",IF(O27>=0.5,""#FFA500"",""#F44336""))})"),"")
A28: Druni Parc Central | B28: Hair | C28: HAIR - ESPEJO | D28: 12.24 | E28: 46084 | F28: =IFERROR(__xludf.DUMMYFUNCTION("""COMPUTED_VALUE"""),"CNC") -> CNC | G28: =IFERROR(__xludf.DUMMYFUNCTION("""COMPUTED_VALUE"""),"CNC") -> CNC | H28: =IFERROR(__xludf.DUMMYFUNCTION("(IFERROR(FILTER(BBDD!$J:$J,BBDD!$G:$G=C28,BBDD!$H:$H=F28,BBDD!$I:$I=G28),""NO TIENE PROCESO""))*D28"),4.5288) -> 4.5288 | I28: =J28+K28 -> 2.1 | J28: =SUMIFS('👷horas'!$J:$J,'👷horas'!$D:$D,A28,'👷horas'!$E:$E,B28,'👷horas'!$F:$F,F28,'👷horas'!$G:$G,G28) -> 2.1 | K28: =SUMIFS('👷horas'!$K:$K,'👷horas'!$D:$D,A28,'👷horas'!$E:$E,B28,'👷horas'!$F:$F,F28,'👷horas'!$G:$G,G28) -> 0 | L28: =I28/D28 -> 0.17156863 | M28: =IF(P28="TERMINADO",0,H28-(J28+K28)) -> 0 | N28: =1-(I28/H28) -> 0.53630101 | O28: =IF(NOT(ISNUMBER(H28)),0,IF(P28="Terminado",1,IF(J28=0,0,MIN(1,J28/H28)))) -> 1 | P28: Terminado | Q28: =IF(COUNTIFS(A:A,A28,P:P,"Terminado")=COUNTIF(A:A,A28),"Terminado",IF(COUNTIFS(A:A,A28,P:P,"En proceso")>0,"En proceso","Pendiente")) -> Terminado | R28: =IFERROR(__xludf.DUMMYFUNCTION("SPARKLINE(O28,{""charttype"",""bar"";""max"",1;""color1"",IF(P28=""Terminado"",""#4CAF50"",IF(O28>=0.5,""#FFA500"",""#F44336""))})"),"")
A29: Druni Parc Central | B29: Hair | C29: HAIR - ESPEJO | D29: 9 | E29: 46084 | F29: =IFERROR(__xludf.DUMMYFUNCTION("""COMPUTED_VALUE"""),"Fabricación") -> Fabricación | G29: =IFERROR(__xludf.DUMMYFUNCTION("""COMPUTED_VALUE"""),"Ensamblaje") -> Ensamblaje | H29: =IFERROR(__xludf.DUMMYFUNCTION("(IFERROR(FILTER(BBDD!$J:$J,BBDD!$G:$G=C29,BBDD!$H:$H=F29,BBDD!$I:$I=G29),""NO TIENE PROCESO""))*D29"),2.88) -> 2.88 | I29: =J29+K29 -> 10.3 | J29: =SUMIFS('👷horas'!$J:$J,'👷horas'!$D:$D,A29,'👷horas'!$E:$E,B29,'👷horas'!$F:$F,F29,'👷horas'!$G:$G,G29) -> 6.3 | K29: =SUMIFS('👷horas'!$K:$K,'👷horas'!$D:$D,A29,'👷horas'!$E:$E,B29,'👷horas'!$F:$F,F29,'👷horas'!$G:$G,G29) -> 4 | L29: =I29/D29 -> 1.1444444 | M29: =IF(P29="TERMINADO",0,H29-(J29+K29)) -> 0 | N29: =1-(I29/H29) -> -2.5763889 | O29: =IF(NOT(ISNUMBER(H29)),0,IF(P29="Terminado",1,IF(J29=0,0,MIN(1,J29/H29)))) -> 1 | P29: Terminado | Q29: =IF(COUNTIFS(A:A,A29,P:P,"Terminado")=COUNTIF(A:A,A29),"Terminado",IF(COUNTIFS(A:A,A29,P:P,"En proceso")>0,"En proceso","Pendiente")) -> Terminado | R29: =IFERROR(__xludf.DUMMYFUNCTION("SPARKLINE(O29,{""charttype"",""bar"";""max"",1;""color1"",IF(P29=""Terminado"",""#4CAF50"",IF(O29>=0.5,""#FFA500"",""#F44336""))})"),"")
A30: Druni Parc Central | B30: Hair | C30: HAIR - ESPEJO | D30: 9 | E30: 46084 | F30: =IFERROR(__xludf.DUMMYFUNCTION("""COMPUTED_VALUE"""),"Fabricación") -> Fabricación | G30: =IFERROR(__xludf.DUMMYFUNCTION("""COMPUTED_VALUE"""),"Colocación de perfiles") -> Colocación de perfiles | H30: =IFERROR(__xludf.DUMMYFUNCTION("(IFERROR(FILTER(BBDD!$J:$J,BBDD!$G:$G=C30,BBDD!$H:$H=F30,BBDD!$I:$I=G30),""NO TIENE PROCESO""))*D30"),1.3499999999999999) -> 1.35 | I30: =J30+K30 -> 7.3333333 | J30: =SUMIFS('👷horas'!$J:$J,'👷horas'!$D:$D,A30,'👷horas'!$E:$E,B30,'👷horas'!$F:$F,F30,'👷horas'!$G:$G,G30) -> 6.8333333 | K30: =SUMIFS('👷horas'!$K:$K,'👷horas'!$D:$D,A30,'👷horas'!$E:$E,B30,'👷horas'!$F:$F,F30,'👷horas'!$G:$G,G30) -> 0.5 | L30: =I30/D30 -> 0.81481481 | M30: =IF(P30="TERMINADO",0,H30-(J30+K30)) -> 0 | N30: =1-(I30/H30) -> -4.4320988 | O30: =IF(NOT(ISNUMBER(H30)),0,IF(P30="Terminado",1,IF(J30=0,0,MIN(1,J30/H30)))) -> 1 | P30: Terminado | Q30: =IF(COUNTIFS(A:A,A30,P:P,"Terminado")=COUNTIF(A:A,A30),"Terminado",IF(COUNTIFS(A:A,A30,P:P,"En proceso")>0,"En proceso","Pendiente")) -> Terminado | R30: =IFERROR(__xludf.DUMMYFUNCTION("SPARKLINE(O30,{""charttype"",""bar"";""max"",1;""color1"",IF(P30=""Terminado"",""#4CAF50"",IF(O30>=0.5,""#FFA500"",""#F44336""))})"),"")
A31: Druni Parc Central | B31: Hair | C31: HAIR - ESPEJO | D31: 9 | E31: 46084 | F31: =IFERROR(__xludf.DUMMYFUNCTION("""COMPUTED_VALUE"""),"Pintura") -> Pintura | G31: =IFERROR(__xludf.DUMMYFUNCTION("""COMPUTED_VALUE"""),"Imprimación/Pintura") -> Imprimación/Pintura | H31: =IFERROR(__xludf.DUMMYFUNCTION("(IFERROR(FILTER(BBDD!$J:$J,BBDD!$G:$G=C31,BBDD!$H:$H=F31,BBDD!$I:$I=G31),""NO TIENE PROCESO""))*D31"),0.9) -> 0.9 | I31: =J31+K31 -> 2 | J31: =SUMIFS('👷horas'!$J:$J,'👷horas'!$D:$D,A31,'👷horas'!$E:$E,B31,'👷horas'!$F:$F,F31,'👷horas'!$G:$G,G31) -> 2 | K31: =SUMIFS('👷horas'!$K:$K,'👷horas'!$D:$D,A31,'👷horas'!$E:$E,B31,'👷horas'!$F:$F,F31,'👷horas'!$G:$G,G31) -> 0 | L31: =I31/D31 -> 0.22222222 | M31: =IF(P31="TERMINADO",0,H31-(J31+K31)) -> 0 | N31: =1-(I31/H31) -> -1.2222222 | O31: =IF(NOT(ISNUMBER(H31)),0,IF(P31="Terminado",1,IF(J31=0,0,MIN(1,J31/H31)))) -> 1 | P31: Terminado | Q31: =IF(COUNTIFS(A:A,A31,P:P,"Terminado")=COUNTIF(A:A,A31),"Terminado",IF(COUNTIFS(A:A,A31,P:P,"En proceso")>0,"En proceso","Pendiente")) -> Terminado | R31: =IFERROR(__xludf.DUMMYFUNCTION("SPARKLINE(O31,{""charttype"",""bar"";""max"",1;""color1"",IF(P31=""Terminado"",""#4CAF50"",IF(O31>=0.5,""#FFA500"",""#F44336""))})"),"")
A32: Druni Cordoba fase 2 | B32: Cupula | C32: CUPULA DE COMPOSITE | D32: 1.3 | E32: 46087 | F32: =IFERROR(__xludf.DUMMYFUNCTION("FILTER(BBDD!H:H,BBDD!G:G=C32)"),"Fabricación") -> Fabricación | G32: =IFERROR(__xludf.DUMMYFUNCTION("FILTER(BBDD!I:I,BBDD!G:G=C32)"),"Ensamblaje") -> Ensamblaje | H32: =IFERROR(__xludf.DUMMYFUNCTION("(IFERROR(FILTER(BBDD!$J:$J,BBDD!$G:$G=C32,BBDD!$H:$H=F32,BBDD!$I:$I=G32),""NO TIENE PROCESO""))*D32"),0.325) -> 0.325 | I32: =J32+K32 -> 13.5 | J32: =SUMIFS('👷horas'!$J:$J,'👷horas'!$D:$D,A32,'👷horas'!$E:$E,B32,'👷horas'!$F:$F,F32,'👷horas'!$G:$G,G32) -> 13 | K32: =SUMIFS('👷horas'!$K:$K,'👷horas'!$D:$D,A32,'👷horas'!$E:$E,B32,'👷horas'!$F:$F,F32,'👷horas'!$G:$G,G32) -> 0.5 | L32: =I32/D32 -> 10.384615 | M32: =IF(P32="TERMINADO",0,H32-(J32+K32)) -> 0 | N32: =1-(I32/H32) -> -40.538462 | O32: =IF(NOT(ISNUMBER(H32)),0,IF(P32="Terminado",1,IF(J32=0,0,MIN(1,J32/H32)))) -> 1 | P32: Terminado | Q32: =IF(COUNTIFS(A:A,A32,P:P,"Terminado")=COUNTIF(A:A,A32),"Terminado",IF(COUNTIFS(A:A,A32,P:P,"En proceso")>0,"En proceso","Pendiente")) -> Terminado | R32: =IFERROR(__xludf.DUMMYFUNCTION("SPARKLINE(O32,{""charttype"",""bar"";""max"",1;""color1"",IF(P32=""Terminado"",""#4CAF50"",IF(O32>=0.5,""#FFA500"",""#F44336""))})"),"")
A33: Druni Cordoba fase 2 | B33: Cupula | C33: CUPULA DE COMPOSITE | D33: 1.3 | E33: 46087 | F33: =IFERROR(__xludf.DUMMYFUNCTION("""COMPUTED_VALUE"""),"Fabricación") -> Fabricación | G33: =IFERROR(__xludf.DUMMYFUNCTION("""COMPUTED_VALUE"""),"Embalaje/carga/descarga material") -> Embalaje/carga/descarga material | H33: =IFERROR(__xludf.DUMMYFUNCTION("(IFERROR(FILTER(BBDD!$J:$J,BBDD!$G:$G=C33,BBDD!$H:$H=F33,BBDD!$I:$I=G33),""NO TIENE PROCESO""))*D33"),0.065) -> 0.065 | I33: =J33+K33 -> 6 | J33: =SUMIFS('👷horas'!$J:$J,'👷horas'!$D:$D,A33,'👷horas'!$E:$E,B33,'👷horas'!$F:$F,F33,'👷horas'!$G:$G,G33) -> 6 | K33: =SUMIFS('👷horas'!$K:$K,'👷horas'!$D:$D,A33,'👷horas'!$E:$E,B33,'👷horas'!$F:$F,F33,'👷horas'!$G:$G,G33) -> 0 | L33: =I33/D33 -> 4.6153846 | M33: =IF(P33="TERMINADO",0,H33-(J33+K33)) -> 0 | N33: =1-(I33/H33) -> -91.307692 | O33: =IF(NOT(ISNUMBER(H33)),0,IF(P33="Terminado",1,IF(J33=0,0,MIN(1,J33/H33)))) -> 1 | P33: Terminado | Q33: =IF(COUNTIFS(A:A,A33,P:P,"Terminado")=COUNTIF(A:A,A33),"Terminado",IF(COUNTIFS(A:A,A33,P:P,"En proceso")>0,"En proceso","Pendiente")) -> Terminado | R33: =IFERROR(__xludf.DUMMYFUNCTION("SPARKLINE(O33,{""charttype"",""bar"";""max"",1;""color1"",IF(P33=""Terminado"",""#4CAF50"",IF(O33>=0.5,""#FFA500"",""#F44336""))})"),"")
A34: Druni Cordoba fase 2 | B34: Cupula | C34: CUPULA DE COMPOSITE | D34: 1.3 | E34: 46087 | F34: =IFERROR(__xludf.DUMMYFUNCTION("""COMPUTED_VALUE"""),"Fabricación") -> Fabricación | G34: =IFERROR(__xludf.DUMMYFUNCTION("""COMPUTED_VALUE"""),"Corte manual") -> Corte manual | H34: =IFERROR(__xludf.DUMMYFUNCTION("(IFERROR(FILTER(BBDD!$J:$J,BBDD!$G:$G=C34,BBDD!$H:$H=F34,BBDD!$I:$I=G34),""NO TIENE PROCESO""))*D34"),0.013000000000000001) -> 0.013 | I34: =J34+K34 -> 15.5 | J34: =SUMIFS('👷horas'!$J:$J,'👷horas'!$D:$D,A34,'👷horas'!$E:$E,B34,'👷horas'!$F:$F,F34,'👷horas'!$G:$G,G34) -> 15.5 | K34: =SUMIFS('👷horas'!$K:$K,'👷horas'!$D:$D,A34,'👷horas'!$E:$E,B34,'👷horas'!$F:$F,F34,'👷horas'!$G:$G,G34) -> 0 | L34: =I34/D34 -> 11.923077 | M34: =IF(P34="TERMINADO",0,H34-(J34+K34)) -> 0 | N34: =1-(I34/H34) -> -1191.3077 | O34: =IF(NOT(ISNUMBER(H34)),0,IF(P34="Terminado",1,IF(J34=0,0,MIN(1,J34/H34)))) -> 1 | P34: Terminado | Q34: =IF(COUNTIFS(A:A,A34,P:P,"Terminado")=COUNTIF(A:A,A34),"Terminado",IF(COUNTIFS(A:A,A34,P:P,"En proceso")>0,"En proceso","Pendiente")) -> Terminado | R34: =IFERROR(__xludf.DUMMYFUNCTION("SPARKLINE(O34,{""charttype"",""bar"";""max"",1;""color1"",IF(P34=""Terminado"",""#4CAF50"",IF(O34>=0.5,""#FFA500"",""#F44336""))})"),"")
A35: Druni CC Biosfera | B35: Selcos metacrilato | C35: BASTIDOR DE METACRILATO RECTO | D35: 36 | E35: 46097 | F35: =IFERROR(__xludf.DUMMYFUNCTION("FILTER(BBDD!H:H,BBDD!G:G=C35)"),"Fabricación") -> Fabricación | G35: =IFERROR(__xludf.DUMMYFUNCTION("FILTER(BBDD!I:I,BBDD!G:G=C35)"),"Ensamblaje") -> Ensamblaje | H35: =IFERROR(__xludf.DUMMYFUNCTION("(IFERROR(FILTER(BBDD!$J:$J,BBDD!$G:$G=C35,BBDD!$H:$H=F35,BBDD!$I:$I=G35),""NO TIENE PROCESO""))*D35"),32.4) -> 32.4 | I35: =J35+K35 -> 32.9 | J35: =SUMIFS('👷horas'!$J:$J,'👷horas'!$D:$D,A35,'👷horas'!$E:$E,B35,'👷horas'!$F:$F,F35,'👷horas'!$G:$G,G35) -> 28.9 | K35: =SUMIFS('👷horas'!$K:$K,'👷horas'!$D:$D,A35,'👷horas'!$E:$E,B35,'👷horas'!$F:$F,F35,'👷horas'!$G:$G,G35) -> 4 | L35: =I35/D35 -> 0.91388889 | M35: =IF(P35="TERMINADO",0,H35-(J35+K35)) -> 0 | N35: =1-(I35/H35) -> -0.015432099 | O35: =IF(NOT(ISNUMBER(H35)),0,IF(P35="Terminado",1,IF(J35=0,0,MIN(1,J35/H35)))) -> 1 | P35: Terminado | Q35: =IF(COUNTIFS(A:A,A35,P:P,"Terminado")=COUNTIF(A:A,A35),"Terminado",IF(COUNTIFS(A:A,A35,P:P,"En proceso")>0,"En proceso","Pendiente")) -> Terminado | R35: =IFERROR(__xludf.DUMMYFUNCTION("SPARKLINE(O35,{""charttype"",""bar"";""max"",1;""color1"",IF(P35=""Terminado"",""#4CAF50"",IF(O35>=0.5,""#FFA500"",""#F44336""))})"),"")
A36: Druni CC Biosfera | B36: Selcos metacrilato | C36: BASTIDOR DE METACRILATO RECTO | D36: 36 | E36: 46097 | F36: =IFERROR(__xludf.DUMMYFUNCTION("""COMPUTED_VALUE"""),"Fabricación") -> Fabricación | G36: =IFERROR(__xludf.DUMMYFUNCTION("""COMPUTED_VALUE"""),"Embalaje/carga/descarga material") -> Embalaje/carga/descarga material | H36: =IFERROR(__xludf.DUMMYFUNCTION("(IFERROR(FILTER(BBDD!$J:$J,BBDD!$G:$G=C36,BBDD!$H:$H=F36,BBDD!$I:$I=G36),""NO TIENE PROCESO""))*D36"),6.12) -> 6.12 | I36: =J36+K36 -> 2 | J36: =SUMIFS('👷horas'!$J:$J,'👷horas'!$D:$D,A36,'👷horas'!$E:$E,B36,'👷horas'!$F:$F,F36,'👷horas'!$G:$G,G36) -> 2 | K36: =SUMIFS('👷horas'!$K:$K,'👷horas'!$D:$D,A36,'👷horas'!$E:$E,B36,'👷horas'!$F:$F,F36,'👷horas'!$G:$G,G36) -> 0 | L36: =I36/D36 -> 0.055555556 | M36: =IF(P36="TERMINADO",0,H36-(J36+K36)) -> 0 | N36: =1-(I36/H36) -> 0.67320261 | O36: =IF(NOT(ISNUMBER(H36)),0,IF(P36="Terminado",1,IF(J36=0,0,MIN(1,J36/H36)))) -> 1 | P36: Terminado | Q36: =IF(COUNTIFS(A:A,A36,P:P,"Terminado")=COUNTIF(A:A,A36),"Terminado",IF(COUNTIFS(A:A,A36,P:P,"En proceso")>0,"En proceso","Pendiente")) -> Terminado | R36: =IFERROR(__xludf.DUMMYFUNCTION("SPARKLINE(O36,{""charttype"",""bar"";""max"",1;""color1"",IF(P36=""Terminado"",""#4CAF50"",IF(O36>=0.5,""#FFA500"",""#F44336""))})"),"")
A37: Druni CC Meridiano fase 2 | B37: Hair | C37: HAIR - ESPEJO | D37: 12.24 | E37: 46097 | F37: =IFERROR(__xludf.DUMMYFUNCTION("FILTER(BBDD!H:H,BBDD!G:G=C37)"),"Fabricación") -> Fabricación | G37: =IFERROR(__xludf.DUMMYFUNCTION("FILTER(BBDD!I:I,BBDD!G:G=C37)"),"Pegado de composite/chapa") -> Pegado de composite/chapa | H37: =IFERROR(__xludf.DUMMYFUNCTION("(IFERROR(FILTER(BBDD!$J:$J,BBDD!$G:$G=C37,BBDD!$H:$H=F37,BBDD!$I:$I=G37),""NO TIENE PROCESO""))*D37"),6.364800000000001) -> 6.3648 | I37: =J37+K37 -> 6 | J37: =SUMIFS('👷horas'!$J:$J,'👷horas'!$D:$D,A37,'👷horas'!$E:$E,B37,'👷horas'!$F:$F,F37,'👷horas'!$G:$G,G37) -> 6 | K37: =SUMIFS('👷horas'!$K:$K,'👷horas'!$D:$D,A37,'👷horas'!$E:$E,B37,'👷horas'!$F:$F,F37,'👷horas'!$G:$G,G37) -> 0 | L37: =I37/D37 -> 0.49019608 | M37: =IF(P37="TERMINADO",0,H37-(J37+K37)) -> 0 | N37: =1-(I37/H37) -> 0.057315234 | O37: =IF(NOT(ISNUMBER(H37)),0,IF(P37="Terminado",1,IF(J37=0,0,MIN(1,J37/H37)))) -> 1 | P37: Terminado | Q37: =IF(COUNTIFS(A:A,A37,P:P,"Terminado")=COUNTIF(A:A,A37),"Terminado",IF(COUNTIFS(A:A,A37,P:P,"En proceso")>0,"En proceso","Pendiente")) -> Terminado | R37: =IFERROR(__xludf.DUMMYFUNCTION("SPARKLINE(O37,{""charttype"",""bar"";""max"",1;""color1"",IF(P37=""Terminado"",""#4CAF50"",IF(O37>=0.5,""#FFA500"",""#F44336""))})"),"")
A38: Druni CC Meridiano fase 2 | B38: Hair | C38: HAIR - ESPEJO | D38: 12.24 | E38: 46097 | F38: =IFERROR(__xludf.DUMMYFUNCTION("""COMPUTED_VALUE"""),"Fabricación") -> Fabricación | G38: =IFERROR(__xludf.DUMMYFUNCTION("""COMPUTED_VALUE"""),"Embalaje/carga/descarga material") -> Embalaje/carga/descarga material | H38: =IFERROR(__xludf.DUMMYFUNCTION("(IFERROR(FILTER(BBDD!$J:$J,BBDD!$G:$G=C38,BBDD!$H:$H=F38,BBDD!$I:$I=G38),""NO TIENE PROCESO""))*D38"),5.6304) -> 5.6304 | I38: =J38+K38 -> 3.5 | J38: =SUMIFS('👷horas'!$J:$J,'👷horas'!$D:$D,A38,'👷horas'!$E:$E,B38,'👷horas'!$F:$F,F38,'👷horas'!$G:$G,G38) -> 3.5 | K38: =SUMIFS('👷horas'!$K:$K,'👷horas'!$D:$D,A38,'👷horas'!$E:$E,B38,'👷horas'!$F:$F,F38,'👷horas'!$G:$G,G38) -> 0 | L38: =I38/D38 -> 0.28594771 | M38: =IF(P38="TERMINADO",0,H38-(J38+K38)) -> 0 | N38: =1-(I38/H38) -> 0.37837454 | O38: =IF(NOT(ISNUMBER(H38)),0,IF(P38="Terminado",1,IF(J38=0,0,MIN(1,J38/H38)))) -> 1 | P38: Terminado | Q38: =IF(COUNTIFS(A:A,A38,P:P,"Terminado")=COUNTIF(A:A,A38),"Terminado",IF(COUNTIFS(A:A,A38,P:P,"En proceso")>0,"En proceso","Pendiente")) -> Terminado | R38: =IFERROR(__xludf.DUMMYFUNCTION("SPARKLINE(O38,{""charttype"",""bar"";""max"",1;""color1"",IF(P38=""Terminado"",""#4CAF50"",IF(O38>=0.5,""#FFA500"",""#F44336""))})"),"")
A39: Druni CC Meridiano fase 2 | B39: Hair | C39: HAIR - ESPEJO | D39: 12.24 | E39: 46097 | F39: =IFERROR(__xludf.DUMMYFUNCTION("""COMPUTED_VALUE"""),"CNC") -> CNC | G39: =IFERROR(__xludf.DUMMYFUNCTION("""COMPUTED_VALUE"""),"CNC") -> CNC | H39: =IFERROR(__xludf.DUMMYFUNCTION("(IFERROR(FILTER(BBDD!$J:$J,BBDD!$G:$G=C39,BBDD!$H:$H=F39,BBDD!$I:$I=G39),""NO TIENE PROCESO""))*D39"),4.5288) -> 4.5288 | I39: =J39+K39 -> 2.0416667 | J39: =SUMIFS('👷horas'!$J:$J,'👷horas'!$D:$D,A39,'👷horas'!$E:$E,B39,'👷horas'!$F:$F,F39,'👷horas'!$G:$G,G39) -> 2.0416667 | K39: =SUMIFS('👷horas'!$K:$K,'👷horas'!$D:$D,A39,'👷horas'!$E:$E,B39,'👷horas'!$F:$F,F39,'👷horas'!$G:$G,G39) -> 0 | L39: =I39/D39 -> 0.16680283 | M39: =IF(P39="TERMINADO",0,H39-(J39+K39)) -> 0 | N39: =1-(I39/H39) -> 0.54918153 | O39: =IF(NOT(ISNUMBER(H39)),0,IF(P39="Terminado",1,IF(J39=0,0,MIN(1,J39/H39)))) -> 1 | P39: Terminado | Q39: =IF(COUNTIFS(A:A,A39,P:P,"Terminado")=COUNTIF(A:A,A39),"Terminado",IF(COUNTIFS(A:A,A39,P:P,"En proceso")>0,"En proceso","Pendiente")) -> Terminado | R39: =IFERROR(__xludf.DUMMYFUNCTION("SPARKLINE(O39,{""charttype"",""bar"";""max"",1;""color1"",IF(P39=""Terminado"",""#4CAF50"",IF(O39>=0.5,""#FFA500"",""#F44336""))})"),"")
A40: Druni CC Meridiano fase 2 | B40: Hair | C40: HAIR - ESPEJO | D40: 9 | E40: 46097 | F40: =IFERROR(__xludf.DUMMYFUNCTION("""COMPUTED_VALUE"""),"Fabricación") -> Fabricación | G40: =IFERROR(__xludf.DUMMYFUNCTION("""COMPUTED_VALUE"""),"Ensamblaje") -> Ensamblaje | H40: =IFERROR(__xludf.DUMMYFUNCTION("(IFERROR(FILTER(BBDD!$J:$J,BBDD!$G:$G=C40,BBDD!$H:$H=F40,BBDD!$I:$I=G40),""NO TIENE PROCESO""))*D40"),2.88) -> 2.88 | I40: =J40+K40 -> 3.7 | J40: =SUMIFS('👷horas'!$J:$J,'👷horas'!$D:$D,A40,'👷horas'!$E:$E,B40,'👷horas'!$F:$F,F40,'👷horas'!$G:$G,G40) -> 3.7 | K40: =SUMIFS('👷horas'!$K:$K,'👷horas'!$D:$D,A40,'👷horas'!$E:$E,B40,'👷horas'!$F:$F,F40,'👷horas'!$G:$G,G40) -> 0 | L40: =I40/D40 -> 0.41111111 | M40: =IF(P40="TERMINADO",0,H40-(J40+K40)) -> 0 | N40: =1-(I40/H40) -> -0.28472222 | O40: =IF(NOT(ISNUMBER(H40)),0,IF(P40="Terminado",1,IF(J40=0,0,MIN(1,J40/H40)))) -> 1 | P40: Terminado | Q40: =IF(COUNTIFS(A:A,A40,P:P,"Terminado")=COUNTIF(A:A,A40),"Terminado",IF(COUNTIFS(A:A,A40,P:P,"En proceso")>0,"En proceso","Pendiente")) -> Terminado | R40: =IFERROR(__xludf.DUMMYFUNCTION("SPARKLINE(O40,{""charttype"",""bar"";""max"",1;""color1"",IF(P40=""Terminado"",""#4CAF50"",IF(O40>=0.5,""#FFA500"",""#F44336""))})"),"")
...

Sheet 👷horas
A1: Timestamp | B1: Fecha | C1: Operario | D1: Proyecto | E1: Lámpara | F1: Área | G1: Proceso | H1: Hora Inicio | I1: Hora Fin | J1: Horas Normales | K1: Horas Extras | L1: Observaciones
B2: 46009 | C2: Ihor Alieksieiev | D2: Druni cc las arenas (Canarias) | E2: Selcos metacrilato | F2: Fabricación | G2: Ensamblaje | J2: 4
B3: 46009 | C3: Serhii Kotluienko | D3: Druni cc las arenas (Canarias) | E3: Selcos metacrilato | F3: Fabricación | G3: Ensamblaje | J3: 4
B4: 46009 | C4: Tetiana Mesriakin | D4: Druni cc las arenas (Canarias) | E4: Selcos metacrilato | F4: Fabricación | G4: Ensamblaje | J4: 4
B5: 46010 | C5: Ihor Alieksieiev | D5: Druni cc la Villa (Canarias) | E5: Parafarmacia | F5: Fabricación | G5: Embalaje/carga/descarga material | J5: 8
B6: 46010 | C6: John Castelblanco | D6: Druni cc la Villa (Canarias) | E6: Hair | F6: CNC | G6: CNC | J6: 1.8 | L6: Corte máquina cnc
B7: 46010 | C7: John Castelblanco | D7: Druni cc la Villa (Canarias) | E7: Hair | F7: CNC | G7: CNC | J7: 0.9 | L7: Corte máquina cnc
B8: 46010 | C8: Serhii Kotluienko | D8: Druni cc las arenas (Canarias) | E8: Selcos metacrilato | F8: Fabricación | G8: Ensamblaje | J8: 8
B9: 46010 | C9: Tetiana Mesriakin | D9: Druni cc las arenas (Canarias) | E9: Selcos metacrilato | F9: Fabricación | G9: Ensamblaje | J9: 8
B10: 46013 | C10: Ihor Alieksieiev | D10: Druni cc la Villa (Canarias) | E10: Cruz | F10: Fabricación | G10: Ensamblaje | J10: 8
B11: 46013 | C11: Serhii Kotluienko | D11: Druni cc las arenas (Canarias) | E11: Selcos metacrilato | F11: Fabricación | G11: Embalaje/carga/descarga material | J11: 4 | L11: y llevar a nave 1
B12: 46013 | C12: Serhii Kotluienko | D12: Druni cc las arenas (Canarias) | E12: Selcos metacrilato | F12: Fabricación | G12: Ensamblaje | J12: 4
B13: 46013 | C13: Tetiana Mesriakin | D13: Druni cc las arenas (Canarias) | E13: Selcos metacrilato | F13: Fabricación | G13: Embalaje/carga/descarga material | J13: 4 | L13: y llevar a nave 1
B14: 46013 | C14: Tetiana Mesriakin | D14: Druni cc las arenas (Canarias) | E14: Selcos metacrilato | F14: Fabricación | G14: Ensamblaje | J14: 4
B15: 46029 | C15: Claudio Peralta | D15: Druni cc la Villa (Canarias) | E15: Parafarmacia | F15: Pintura | G15: Imprimación/Pintura | J15: 4 | L15: Imprimación
B16: 46029 | C16: Claudio Peralta | D16: Druni cc la Villa (Canarias) | E16: Hair | F16: Pintura | G16: Imprimación/Pintura | J16: 1.5 | L16: Imprimación
B17: 46030 | C17: Claudio Peralta | D17: Druni cc la Villa (Canarias) | E17: Parafarmacia | F17: Pintura | G17: Imprimación/Pintura | J17: 5 | L17: Pintura
B18: 46034 | C18: Claudio Peralta | D18: Contract + | E18: Nave | F18: Limpieza | G18: Limpieza | J18: 8
B19: 46034 | C19: Ihor Alieksieiev | D19: Druni cc la Villa (Canarias) | E19: Parafarmacia | F19: Fabricación | G19: Embalaje/carga/descarga material | J19: 0.25
B20: 46034 | C20: Ihor Alieksieiev | D20: Druni cc la Villa (Canarias) | E20: Cruz | F20: Fabricación | G20: Embalaje/carga/descarga material | J20: 0.25
B21: 46034 | C21: Ihor Alieksieiev | D21: Druni cc la Villa (Canarias) | E21: Parafarmacia | F21: Carga de Material | G21: Embalaje/carga/descarga material | J21: 0.5 | L21: Transporte material
B22: 46034 | C22: Ihor Alieksieiev | D22: Druni cc la Villa (Canarias) | E22: Cruz | F22: Carga de Material | G22: Embalaje/carga/descarga material | J22: 0.5 | L22: Transporte material
B23: 46034 | C23: Ihor Alieksieiev | D23: Contract + | E23: Nave | F23: Limpieza | G23: Limpieza | J23: 6.5
B24: 46034 | C24: Serhii Kotluienko | D24: Druni cc la Villa (Canarias) | E24: Parafarmacia | F24: Fabricación | G24: Embalaje/carga/descarga material | J24: 0.25
B25: 46034 | C25: Serhii Kotluienko | D25: Druni cc la Villa (Canarias) | E25: Cruz | F25: Fabricación | G25: Embalaje/carga/descarga material | J25: 0.25
B26: 46034 | C26: Serhii Kotluienko | D26: Druni cc la Villa (Canarias) | E26: Parafarmacia | F26: Carga de Material | G26: Embalaje/carga/descarga material | J26: 0.5 | L26: Transporte material
B27: 46034 | C27: Serhii Kotluienko | D27: Druni cc la Villa (Canarias) | E27: Cruz | F27: Carga de Material | G27: Embalaje/carga/descarga material | J27: 0.5 | L27: Transporte material
B28: 46034 | C28: Serhii Kotluienko | D28: Contract + | E28: Nave | F28: Limpieza | G28: Limpieza | J28: 6.5
B29: 46034 | C29: Tetiana Mesriakin | D29: Druni cc la Villa (Canarias) | E29: Hair | F29: Fabricación | G29: Embalaje/carga/descarga material | J29: 1.5
B30: 46034 | C30: Tetiana Mesriakin | D30: Contract + | E30: Nave | F30: Limpieza | G30: Limpieza | J30: 6.5
B31: 46035 | C31: Claudio Peralta | D31: Contract + | E31: Nave | F31: Limpieza | G31: Limpieza | J31: 8
B32: 46035 | C32: Ihor Alieksieiev | D32: Contract + | E32: Nave | F32: Limpieza | G32: Limpieza | J32: 8
B33: 46035 | C33: John Castelblanco | D33: Druni Cordoba fase 2 | E33: Cruz | F33: CNC | G33: CNC | J33: 1.5 | L33: Corte máquina cnc
B34: 46035 | C34: Serhii Kotluienko | D34: Contract + | E34: Nave | F34: Limpieza | G34: Limpieza | J34: 8
B35: 46035 | C35: Tetiana Mesriakin | D35: Contract + | E35: Nave | F35: Limpieza | G35: Limpieza | J35: 8
B36: 46036 | C36: Claudio Peralta | D36: Contract + | E36: Nave | F36: Limpieza | G36: Limpieza | J36: 8
B37: 46036 | C37: Ihor Alieksieiev | D37: Contract + | E37: Nave | F37: Limpieza | G37: Limpieza | J37: 8
B38: 46036 | C38: John Castelblanco | D38: Druni cc la Villa (Canarias) | E38: Hair | F38: CNC | G38: CNC | J38: 0.5 | L38: Corte máquina cnc
